Workbook
Name BASELINES: #REF!
Name basetable: #REF!
Name CISCONTROLS: #REF!
Name controls: #REF!
Name controls2: #REF!
Name ljhdsf: #REF!
Name newcontrols: #REF!
Name newNIST: #REF!
Name NIST: #REF!
Name NISTCONTROLS: #REF!
Name nxwalkr4: #REF!
Name XWALKR4: #REF!

Sheet Info
C2: Important Notes About This Workbook:
C3: Conditional Formatting of each Control ## worksheet is dependent upon two criteria: 1. The Value selected for "Implementation Group" on the Dashboard worksheet 2. The Value of columns A and B of each Control ## worksheet Selecting a value on the Dashboard worksheet controls which Safeguards are suppressed on both the Control ## and ScoringTables worksheets.
C5: Criticality weightings are derived from two factors: 1. The number of dependent Safeguards defined within the Controls Assessment Specification 2. The number of mitigations defined within the Community Defense Model
C7: WARNING: This workbook is delivered as-is and is not intended for risk assessment purposes. The measurements performed within this workbook are derived from the measurements described in the CIS Controls Assessment Specification, which is licensed under a Creative Commons Attribution-NonCommercial-No Derivatives 4.0 Internation Public License. In some cases, the measurements prescribed deviate considerably from the CAS, and are (therefore) not to be shared or utilized outside the State of Oregon Executive Branch.
B9: CIS-CAS Alignment Notes:
B10: 1.01 | C10: Calculates "Completeness Score" as a ratio of expected elements rather than assets
B11: 1.02 | C11: Calculates score utilizing "first seen" date rather than a "rescan" after 7 days
B12: 1.03 | C12: Discovery Coverage is calculated based on leasable IP rather than discovered assets, "compliance" calculation has a default of 69%.
B13: 1.04 | C13: Aligns with CIS-CAS
B14: 1.05 | C14: Aligns with CIS-CAS
B15: 2.01 | C15: Calculates score as a ratio of expected elements rather than assets
B16: 2.02 | C16: Aligns with CIS-CAS
B17: 2.03 | C17: Calculates score utilizing "first seen" date rather than a "rescan" after 7 days
B18: 2.04 | C18: Aligns with CIS-CAS
B19: 2.05 | C19: Aligns with CIS-CAS
B20: 2.06 | C20: Aligns with CIS-CAS
B21: 2.07 | C21: Aligns with CIS-CAS
... B162: 18.05 | C162: Aligns with CIS-CAS
C165: For more information regarding the CIS Controls or Controls Assessment Specification, please refer to: http://www.cisecurity.org/controls/

Sheet GlobalSettings
B2: Implementation Group Assesed: | C2: 0 | D2: For CSS Assessments, Select "0"
B4: Assessment Date: | C4: 45901
B6: Assessment Target: | C6: 0.7
B8: Governance Document Update/Review Target (months): | C8: 24 | D8: To align with Statewide Standard for review of Policies/Procedures/Processes, set to "24"
B10: Provide Partial Credit for "Overdue" Governance Items: | C10: Yes | D10: Overrides zero scores for out-of-date items and adjusts score by [Assessment Target minus 1%]
B12: Provide Partial Credit for "Overdue" Inventory Items: | C12: Yes | D12: Overrides zero scores for out-of-date items and adjusts score by half
B14: Completion Date: | C14: 45930

Sheet Dashboards
BQ19: Target % or Above - Meets Expectations
BQ20: 51% - Target % - Needs Improvement
BQ21: 26% - 50% - Poor
BQ22: 1% - 25% - Extremely Poor
BQ23: Not Implemented
BQ24: Not Assessed
AY31: Target % or Above - Meets Expectations
AY32: 51% - Target % - Needs Improvement
AY33: 26% - 50% - Poor
AY34: 1% - 25% - Extremely Poor
AY35: Not Implemented
AY36: Not Assessed

Sheet Artifacts
C2: Artifact ID | D2: Artifact Name | E2: Artifact Provided | F2: Artifact Review Date
A3: 0 | C3: GV01 | D3: Enterprise Asset Inventory | E3: Artifact Not Provided | F3: 1
A4: 0 | C4: GV03.a | D4: Configuration Standards: Operating Systems & Software | E4: Artifact Not Provided | F4: 1
A5: 0 | C5: GV03.b | D5: Configuration Standards: Active Discovery Tool(s) | E5: Artifact Not Provided | F5: 1
A6: 0 | C6: GV03.c | D6: Configuration Standards: Encryption Software / Mecnanisms for End-User Devices | E6: Artifact Not Provided | F6: 1
A7: 0 | C7: GV03.d | D7: Configuration Standards: DNS Servers | E7: Artifact Not Provided | F7: 1
A8: 0 | C8: GV03.e | D8: Configuration Standards: Authorized Remote Access Assets | E8: Artifact Not Provided | F8: 1
A9: 0 | C9: GV03.f | D9: Configuration Standards: Automated Patch Management Software | E9: Artifact Not Provided | F9: 1
A10: 0 | C10: GV03.g | D10: Configuration Standards: Vulnerability Scanners / Scanning Software | E10: Artifact Not Provided | F10: 1
A11: 0 | C11: GV03.h | D11: Configuration Standards: MFA Mechanisms for Admin Accounts, Remote Access, & Accounts on Externally-Exposed Applications | E11: Artifact Not Provided | F11: 1
C12: GV04 | D12: Enterprise Network Architecture Documentation | E12: Artifact Not Provided | F12: 1
A13: 0 | C13: GV05 | D13: Authorized Software Inventory | E13: Artifact Not Provided | F13: 1
A14: 0 | C14: GV09 | D14: Approved Configuration(s) for Allowlisting Software | E14: Artifact Not Provided | F14: 1
A15: 0 | C15: GV10 | D15: Organization's Data Management Process | E15: Artifact Not Provided | F15: 1
A16: 0 | C16: GV12 | D16: Sensitive Data Inventory | E16: Artifact Not Provided | F16: 1
A17: 0 | C17: GV18 | D17: Enterprise Assets Storing Sensitive Data | E17: Artifact Not Provided | F17: 1
A18: 0 | C18: GV20 | D18: Unique Password Policy | E18: Artifact Not Provided | F18: 1
A19: 0 | C19: GV22 | D19: Inventory of Accounts | E19: Artifact Not Provided | F19: 1
C20: GV23 | D20: Inventory of Authentication and Authorization Systems | E20: Artifact Not Provided | F20: 1
A21: 0 | C21: GV24 | D21: Authorized Automated Patch Management Software | E21: Artifact Not Provided | F21: 1
A22: 0 | C22: GV25 | D22: List of Vulnerability Scanning Software | E22: Artifact Not Provided | F22: 1
A23: 0 | C23: GV26 | D23: Agency Audit Log Management Process (inherited from Enterprise) | E23: Artifact Not Provided | F23: 1
A24: 0 | C24: GV31 | D24: List of Authorized Anti‐malware Software | E24: Artifact Not Provided | F24: 1
C25: GV35 | D25: Assets that are Part of the Network Infrastructure | E25: Artifact Not Provided | F25: 1
A26: 0 | C26: GV43 | D26: List of workforce members | E26: Artifact Not Provided | F26: 1
A27: 0 | C27: GV44 | D27: Service Provider Inventory List | E27: Artifact Not Provided | F27: 1
C28: GV45 | D28: Service Provider Management Policy | E28: Artifact Not Provided | F28: 1
C29: GV47 | D29: Inventory of Third-Party Software Components | E29: Artifact Not Provided | F29: 1
C30: GV48 | D30: Process to Accept and Address Software Vulnerabilities | E30: Artifact Not Provided | F30: 1
C31: GV49 | D31: Secure Application Development Process | E31: Artifact Not Provided | F31: 1
A32: 0 | C32: GV51 | D32: Agency Incident Response Documentation | E32: Artifact Not Provided | F32: 1
C33: GV52 | D33: Agency Incident Response Process | E33: Artifact Not Provided | F33: 1
A34: 9 | B34: 2 | C34: GV53 | D34: Penetration Testing Program Documentation | E34: Artifact Not Provided | F34: 1
A35: 0 | C35: GV54 | D35: Most recent external penetration test report for the organization | E35: Artifact Not Provided | F35: 1
C36: GV55 | D36: Most recent internal penetration test report for the organization | E36: Artifact Not Provided | F36: 1
A37: 0 | C37: AD01 | D37: IP Address Management Documentation for the Organization | E37: Artifact Not Provided | F37: 1
A38: 0 | C38: AD02 | D38: Agency policy documentation that defines the timeframe for removing unauthorized devices | E38: Artifact Not Provided | F38: 1
A39: 0 | C39: AD03 | D39: List of Active Discovery Tool(s) Used by the Organization | E39: Artifact Not Provided | F39: 1
A40: 0 | C40: AD04 | D40: Exception Documentation for Unsupported Software That is Necessary for the Fulfillment of the Organization's Mission | E40: Artifact Not Provided | F40: 1
A41: 0 | C41: AD05 | D41: Policy Documentation That Defines the Timeframe Between Consecutive Active Software Discovery Scans | E41: Artifact Not Provided | F41: 1
...

Sheet ScoringTables
B2: Safeguard | D2: IG | E2: Dep | F2: MITRE 5 | G2: Criticality | H2: Weight | I2: Score | L2: Control | N2: Agency Score | O2: Weight | P2: Residual | Q2: 0-25 | R2: 26-50 | S2: 51-X | T2: X-100 | U2: HIDE | V2: Enterprise Average | W2: Target
B3: 1.01 | C3: Establish and Maintain Detailed Enterprise Asset Inventory | D3: 1 | E3: 65 | F3: 0 | G3: =IF(OR(E3>10,F3>5),"Critical",IF(OR(AND(E3>0,E3<11),AND(F3>0,F3<6)),"High","Medium")) -> Critical | H3: =IF(OR(GlobalSettings!$C$2=0,D3<=GlobalSettings!$C$2),IF(G3="Critical",5,IF(G3="High",3,(IF(G3="Medium",1,0)))),0) -> 5 | I3: ='Control 01'!F16 -> 0 | J3: =IF(OR(GlobalSettings!$C$2=0,D3<=GlobalSettings!$C$2),'Control 01'!E18,"") -> Safeguard Scoring Incomplete | L3: 1 | M3: Inventory and Control of Enterprise Assets | N3: =IFERROR(IF(U3=0,SUMPRODUCT(I3:I7,H3:H7)/SUM(H3:H7),"N/A"),0) -> 0 | O3: =IF(U3=0,SUM(H3:H7),0) -> 6 | P3: =IF(U3=0,1-N3,0) -> 1 | Q3: =IF(U3=0,IF($N3<=0.25,$N3,0),0) -> 0 | R3: =IF(U3=0,IF(AND($N3>=0.25001,$N3<=0.5),$N3,0),0) -> 0 | S3: =IF(U3=0,IF(AND($N3>=0.50001,$N3<=(GlobalSettings!$C$6-0.00001)),$N3,0),0) -> 0 | T3: =IF(U3=0,IF($N3>=GlobalSettings!$C$6,$N3,0),0) -> 0 | U3: =IF('Control 01'!$F$2="Not Assessed",1,0) -> 0 | V3: 0.610288 | W3: =GlobalSettings!$C$6 -> 0.7
B4: 1.02 | C4: Address Unauthorized Assets | D4: 1 | E4: 0 | F4: 0 | G4: =IF(OR(E4>10,F4>5),"Critical",IF(OR(AND(E4>0,E4<11),AND(F4>0,F4<6)),"High","Medium")) -> Medium | H4: =IF(OR(GlobalSettings!$C$2=0,D4<=GlobalSettings!$C$2),IF(G4="Critical",5,IF(G4="High",3,(IF(G4="Medium",1,0)))),0) -> 1 | I4: ='Control 01'!F26 -> 0 | J4: =IF(OR(GlobalSettings!$C$2=0,D4<=GlobalSettings!$C$2),'Control 01'!E28,"") -> Safeguard Scoring Incomplete | L4: 2 | M4: Inventory and Control of Software Assets | N4: =IFERROR(IF(U4=0,SUMPRODUCT(I8:I14,H8:H14)/SUM(H8:H14),"N/A"),0) -> 0 | O4: =IF(U4=0,SUM(H8:H14),0) -> 10 | P4: =IF(U4=0,1-N4,0) -> 1 | Q4: =IF(U4=0,IF($N4<=0.25,$N4,0),0) -> 0 | R4: =IF(U4=0,IF(AND($N4>=0.25001,$N4<=0.5),$N4,0),0) -> 0 | S4: =IF(U4=0,IF(AND($N4>=0.50001,$N4<=(GlobalSettings!$C$6-0.00001)),$N4,0),0) -> 0 | T4: =IF(U4=0,IF($N4>=GlobalSettings!$C$6,$N4,0),0) -> 0 | U4: =IF('Control 02'!$F$2="Not Assessed",1,0) -> 0 | V4: 0.616896 | W4: =GlobalSettings!$C$6 -> 0.7
B5: 1.03 | C5: Utilize an Active Discovery Tool | D5: 2 | E5: 0 | F5: 0 | G5: =IF(OR(E5>10,F5>5),"Critical",IF(OR(AND(E5>0,E5<11),AND(F5>0,F5<6)),"High","Medium")) -> Medium | H5: =IF(D5<=GlobalSettings!$C$2,IF(G5="Critical",5,IF(G5="High",3,(IF(G5="Medium",1,0)))),0) -> 0 | I5: ='Control 01'!F40 -> 0 | J5: =IF(D5<=GlobalSettings!$C$2,'Control 01'!E56,"") | L5: 3 | M5: Data Protection | N5: =IFERROR(IF(U5=0,SUMPRODUCT(I15:I28,H15:H28)/SUM(H15:H28),"N/A"),0) -> 0 | O5: =IF(U5=0,SUM(H15:H28),0) -> 12 | P5: =IF(U5=0,1-N5,0) -> 1 | Q5: =IF(U5=0,IF($N5<=0.25,$N5,0),0) -> 0 | R5: =IF(U5=0,IF(AND($N5>=0.25001,$N5<=0.5),$N5,0),0) -> 0 | S5: =IF(U5=0,IF(AND($N5>=0.50001,$N5<=(GlobalSettings!$C$6-0.00001)),$N5,0),0) -> 0 | T5: =IF(U5=0,IF($N5>=GlobalSettings!$C$6,$N5,0),0) -> 0 | U5: =IF('Control 03'!$F$2="Not Assessed",1,0) -> 0 | V5: 0.5743 | W5: =GlobalSettings!$C$6 -> 0.7
B6: 1.04 | C6: Use Dynamic Host Configuration Protocol (DHCP) Logging to Update Enterprise Asset Inventory | D6: 2 | E6: 0 | F6: 0 | G6: =IF(OR(E6>10,F6>5),"Critical",IF(OR(AND(E6>0,E6<11),AND(F6>0,F6<6)),"High","Medium")) -> Medium | H6: =IF(D6<=GlobalSettings!$C$2,IF(G6="Critical",5,IF(G6="High",3,(IF(G6="Medium",1,0)))),0) -> 0 | I6: ='Control 01'!F55 -> 0 | J6: =IF(D6<=GlobalSettings!$C$2,'Control 01'!E57,"") | L6: 4 | M6: Secure Configuration of Enterprise Assets and Software | N6: =IFERROR(IF(U6=0,SUMPRODUCT(I29:I40,H29:H40)/SUM(H29:H40),"N/A"),0) -> 0 | O6: =IF(U6=0,SUM(H29:H40),0) -> 15 | P6: =IF(U6=0,1-N6,0) -> 1 | Q6: =IF(U6=0,IF($N6<=0.25,$N6,0),0) -> 0 | R6: =IF(U6=0,IF(AND($N6>=0.25001,$N6<=0.5),$N6,0),0) -> 0 | S6: =IF(U6=0,IF(AND($N6>=0.50001,$N6<=(GlobalSettings!$C$6-0.00001)),$N6,0),0) -> 0 | T6: =IF(U6=0,IF($N6>=GlobalSettings!$C$6,$N6,0),0) -> 0 | U6: =IF('Control 04'!$F$2="Not Assessed",1,0) -> 0 | V6: 0.597856 | W6: =GlobalSettings!$C$6 -> 0.7
B7: 1.05 | C7: Use a Passive Asset Discovery Tool | D7: 3 | E7: 0 | F7: 0 | G7: =IF(OR(E7>10,F7>5),"Critical",IF(OR(AND(E7>0,E7<11),AND(F7>0,F7<6)),"High","Medium")) -> Medium | H7: =IF(D7<=GlobalSettings!$C$2,IF(G7="Critical",5,IF(G7="High",3,(IF(G7="Medium",1,0)))),0) -> 0 | I7: ='Control 01'!F66 -> 0 | J7: =IF(D7<=GlobalSettings!$C$2,'Control 01'!E68,"") | L7: 5 | M7: Account Management | N7: =IFERROR(IF(U7=0,SUMPRODUCT(I41:I46,H41:H46)/SUM(H41:H46),"N/A"),0) -> 0 | O7: =IF(U7=0,SUM(H41:H46),0) -> 16 | P7: =IF(U7=0,1-N7,0) -> 1 | Q7: =IF(U7=0,IF($N7<=0.25,$N7,0),0) -> 0 | R7: =IF(U7=0,IF(AND($N7>=0.25001,$N7<=0.5),$N7,0),0) -> 0 | S7: =IF(U7=0,IF(AND($N7>=0.50001,$N7<=(GlobalSettings!$C$6-0.00001)),$N7,0),0) -> 0 | T7: =IF(U7=0,IF($N7>=GlobalSettings!$C$6,$N7,0),0) -> 0 | U7: =IF('Control 05'!$F$2="Not Assessed",1,0) -> 0 | V7: 0.698096 | W7: =GlobalSettings!$C$6 -> 0.7
B8: 2.01 | C8: Establish and Maintain a Software Inventory | D8: 1 | E8: 49 | F8: 0 | G8: =IF(OR(E8>10,F8>5),"Critical",IF(OR(AND(E8>0,E8<11),AND(F8>0,F8<6)),"High","Medium")) -> Critical | H8: =IF(OR(GlobalSettings!$C$2=0,D8<=GlobalSettings!$C$2),IF(G8="Critical",5,IF(G8="High",3,(IF(G8="Medium",1,0)))),0) -> 5 | I8: ='Control 02'!F17 -> 0 | J8: =IF(OR(GlobalSettings!$C$2=0,D8<=GlobalSettings!$C$2),'Control 02'!E19,"") -> Safeguard Scoring Incomplete | L8: 6 | M8: Access Control Management | N8: =IFERROR(IF(U8=0,SUMPRODUCT(I47:I54,H47:H54)/SUM(H47:H54),"N/A"),0) -> 0 | O8: =IF(U8=0,SUM(H47:H54),0) -> 16 | P8: =IF(U8=0,1-N8,0) -> 1 | Q8: =IF(U8=0,IF($N8<=0.25,$N8,0),0) -> 0 | R8: =IF(U8=0,IF(AND($N8>=0.25001,$N8<=0.5),$N8,0),0) -> 0 | S8: =IF(U8=0,IF(AND($N8>=0.50001,$N8<=(GlobalSettings!$C$6-0.00001)),$N8,0),0) -> 0 | T8: =IF(U8=0,IF($N8>=GlobalSettings!$C$6,$N8,0),0) -> 0 | U8: =IF('Control 06'!$F$2="Not Assessed",1,0) -> 0 | V8: 0.50008 | W8: =GlobalSettings!$C$6 -> 0.7
B9: 2.02 | C9: Ensure Authorized Software is Currently Supported | D9: 1 | E9: 0 | F9: 0 | G9: =IF(OR(E9>10,F9>5),"Critical",IF(OR(AND(E9>0,E9<11),AND(F9>0,F9<6)),"High","Medium")) -> Medium | H9: =IF(OR(GlobalSettings!$C$2=0,D9<=GlobalSettings!$C$2),IF(G9="Critical",5,IF(G9="High",3,(IF(G9="Medium",1,0)))),0) -> 1 | I9: ='Control 02'!F34 -> 0 | J9: =IF(OR(GlobalSettings!$C$2=0,D9<=GlobalSettings!$C$2),'Control 02'!E36,"") -> Safeguard Scoring Incomplete | L9: 7 | M9: Continuous Vulnerability Management | N9: =IFERROR(IF(U9=0,SUMPRODUCT(I55:I61,H55:H61)/SUM(H55:H61),"N/A"),0) -> 0 | O9: =IF(U9=0,SUM(H55:H61),0) -> 8 | P9: =IF(U9=0,1-N9,0) -> 1 | Q9: =IF(U9=0,IF($N9<=0.25,$N9,0),0) -> 0 | R9: =IF(U9=0,IF(AND($N9>=0.25001,$N9<=0.5),$N9,0),0) -> 0 | S9: =IF(U9=0,IF(AND($N9>=0.50001,$N9<=(GlobalSettings!$C$6-0.00001)),$N9,0),0) -> 0 | T9: =IF(U9=0,IF($N9>=GlobalSettings!$C$6,$N9,0),0) -> 0 | U9: =IF('Control 07'!$F$2="Not Assessed",1,0) -> 0 | V9: 0.693952 | W9: =GlobalSettings!$C$6 -> 0.7
B10: 2.03 | C10: Address Unauthorized Software | D10: 1 | E10: 2 | F10: 3 | G10: =IF(OR(E10>10,F10>5),"Critical",IF(OR(AND(E10>0,E10<11),AND(F10>0,F10<6)),"High","Medium")) -> High | H10: =IF(OR(GlobalSettings!$C$2=0,D10<=GlobalSettings!$C$2),IF(G10="Critical",5,IF(G10="High",3,(IF(G10="Medium",1,0)))),0) -> 3 | I10: ='Control 02'!F45 -> 0 | J10: =IF(OR(GlobalSettings!$C$2=0,D10<=GlobalSettings!$C$2),'Control 02'!E47,"") -> Safeguard Scoring Incomplete | L10: 8 | M10: Audit Log Management | N10: =IFERROR(IF(U10=0,SUMPRODUCT(I62:I73,H62:H73)/SUM(H62:H73),"N/A"),0) -> 0 | O10: =IF(U10=0,SUM(H62:H73),0) -> 18 | P10: =IF(U10=0,1-N10,0) -> 1 | Q10: =IF(U10=0,IF($N10<=0.25,$N10,0),0) -> 0 | R10: =IF(U10=0,IF(AND($N10>=0.25001,$N10<=0.5),$N10,0),0) -> 0 | S10: =IF(U10=0,IF(AND($N10>=0.50001,$N10<=(GlobalSettings!$C$6-0.00001)),$N10,0),0) -> 0 | T10: =IF(U10=0,IF($N10>=GlobalSettings!$C$6,$N10,0),0) -> 0 | U10: =IF('Control 08'!$F$2="Not Assessed",1,0) -> 0 | V10: 0.632016 | W10: =GlobalSettings!$C$6 -> 0.7
B11: 2.04 | C11: Utilize Automated Software Inventory Tools | D11: 2 | E11: 0 | F11: 0 | G11: =IF(OR(E11>10,F11>5),"Critical",IF(OR(AND(E11>0,E11<11),AND(F11>0,F11<6)),"High","Medium")) -> Medium | H11: =IF(OR(GlobalSettings!$C$2=0,D11<=GlobalSettings!$C$2),IF(G11="Critical",5,IF(G11="High",3,(IF(G11="Medium",1,0)))),0) -> 1 | I11: ='Control 02'!F55 -> 0 | J11: =IF(OR(GlobalSettings!$C$2=0,D11<=GlobalSettings!$C$2),'Control 02'!E57,"") -> Safeguard Scoring Incomplete | L11: 9 | M11: Email and Web Browser Protections | N11: =IFERROR(IF(U11=0,SUMPRODUCT(I74:I80,H74:H80)/SUM(H74:H80),"N/A"),0) -> 0 | O11: =IF(U11=0,SUM(H74:H80),0) -> 2 | P11: =IF(U11=0,1-N11,0) -> 1 | Q11: =IF(U11=0,IF($N11<=0.25,$N11,0),0) -> 0 | R11: =IF(U11=0,IF(AND($N11>=0.25001,$N11<=0.5),$N11,0),0) -> 0 | S11: =IF(U11=0,IF(AND($N11>=0.50001,$N11<=(GlobalSettings!$C$6-0.00001)),$N11,0),0) -> 0 | T11: =IF(U11=0,IF($N11>=GlobalSettings!$C$6,$N11,0),0) -> 0 | U11: =IF('Control 09'!$F$2="Not Assessed",1,0) -> 0 | V11: 0.628768 | W11: =GlobalSettings!$C$6 -> 0.7
B12: 2.05 | C12: Allowlist Authorized Software | D12: 2 | E12: 1 | F12: 3 | G12: =IF(OR(E12>10,F12>5),"Critical",IF(OR(AND(E12>0,E12<11),AND(F12>0,F12<6)),"High","Medium")) -> High | H12: =IF(D12<=GlobalSettings!$C$2,IF(G12="Critical",5,IF(G12="High",3,(IF(G12="Medium",1,0)))),0) -> 0 | I12: ='Control 02'!F68 -> 0 | J12: =IF(D12<=GlobalSettings!$C$2,'Control 02'!E70,"") | L12: 10 | M12: Malware Defenses | N12: =IFERROR(IF(U12=0,SUMPRODUCT(I81:I87,H81:H87)/SUM(H81:H87),"N/A"),0) -> 0 | O12: =IF(U12=0,SUM(H81:H87),0) -> 7 | P12: =IF(U12=0,1-N12,0) -> 1 | Q12: =IF(U12=0,IF($N12<=0.25,$N12,0),0) -> 0 | R12: =IF(U12=0,IF(AND($N12>=0.25001,$N12<=0.5),$N12,0),0) -> 0 | S12: =IF(U12=0,IF(AND($N12>=0.50001,$N12<=(GlobalSettings!$C$6-0.00001)),$N12,0),0) -> 0 | T12: =IF(U12=0,IF($N12>=GlobalSettings!$C$6,$N12,0),0) -> 0 | U12: =IF('Control 10'!$F$2="Not Assessed",1,0) -> 0 | V12: 0.85904 | W12: =GlobalSettings!$C$6 -> 0.7
B13: 2.06 | C13: Allowlist Authorized Libraries | D13: 2 | E13: 0 | F13: 1 | G13: =IF(OR(E13>10,F13>5),"Critical",IF(OR(AND(E13>0,E13<11),AND(F13>0,F13<6)),"High","Medium")) -> High | H13: =IF(D13<=GlobalSettings!$C$2,IF(G13="Critical",5,IF(G13="High",3,(IF(G13="Medium",1,0)))),0) -> 0 | I13: ='Control 02'!F79 -> 0 | J13: =IF(D13<=GlobalSettings!$C$2,'Control 02'!E81,"") | L13: 11 | M13: Data Recovery | N13: =IFERROR(IF(U13=0,SUMPRODUCT(I88:I92,H88:H92)/SUM(H88:H92),"N/A"),0) -> 0 | O13: =IF(U13=0,SUM(H88:H92),0) -> 8 | P13: =IF(U13=0,1-N13,0) -> 1 | Q13: =IF(U13=0,IF($N13<=0.25,$N13,0),0) -> 0 | R13: =IF(U13=0,IF(AND($N13>=0.25001,$N13<=0.5),$N13,0),0) -> 0 | S13: =IF(U13=0,IF(AND($N13>=0.50001,$N13<=(GlobalSettings!$C$6-0.00001)),$N13,0),0) -> 0 | T13: =IF(U13=0,IF($N13>=GlobalSettings!$C$6,$N13,0),0) -> 0 | U13: =IF('Control 11'!$F$2="Not Assessed",1,0) -> 0 | V13: 0.7625 | W13: =GlobalSettings!$C$6 -> 0.7
B14: 2.07 | C14: Allowlist Authorized Scripts | D14: 3 | E14: 0 | F14: 2 | G14: =IF(OR(E14>10,F14>5),"Critical",IF(OR(AND(E14>0,E14<11),AND(F14>0,F14<6)),"High","Medium")) -> High | H14: =IF(D14<=GlobalSettings!$C$2,IF(G14="Critical",5,IF(G14="High",3,(IF(G14="Medium",1,0)))),0) -> 0 | I14: ='Control 02'!F90 -> 0 | J14: =IF(D14<=GlobalSettings!$C$2,'Control 02'!E92,"") | L14: 12 | M14: Network Infrastructure Management | N14: =IFERROR(IF(U14=0,SUMPRODUCT(I93:I100,H93:H100)/SUM(H93:H100),"N/A"),0) -> N/A | O14: =IF(U14=0,SUM(H93:H100),0) -> 0 | P14: =IF(U14=0,1-N14,0) -> 0 | Q14: =IF(U14=0,IF($N14<=0.25,$N14,0),0) -> 0 | R14: =IF(U14=0,IF(AND($N14>=0.25001,$N14<=0.5),$N14,0),0) -> 0 | S14: =IF(U14=0,IF(AND($N14>=0.50001,$N14<=(GlobalSettings!$C$6-0.00001)),$N14,0),0) -> 0 | T14: =IF(U14=0,IF($N14>=GlobalSettings!$C$6,$N14,0),0) -> 0 | U14: =IF('Control 12'!$F$2="Not Assessed",1,0) -> 1 | V14: 0 | W14: =GlobalSettings!$C$6 -> 0.7
B15: 3.01 | C15: Establish and Maintain a Data Management Process | D15: 1 | E15: 4 | F15: 1 | G15: =IF(OR(E15>10,F15>5),"Critical",IF(OR(AND(E15>0,E15<11),AND(F15>0,F15<6)),"High","Medium")) -> High | H15: =IF(OR(GlobalSettings!$C$2=0,D15<=GlobalSettings!$C$2),IF(G15="Critical",5,IF(G15="High",3,(IF(G15="Medium",1,0)))),0) -> 3 | I15: ='Control 03'!F12 -> 0 | J15: =IF(OR(GlobalSettings!$C$2=0,D15<=GlobalSettings!$C$2),'Control 03'!E14,"") -> Safeguard Scoring Incomplete | L15: 13 | M15: Network Monitoring & Defense | N15: =IFERROR(IF(U15=0,SUMPRODUCT(I101:I111,H101:H111)/SUM(H101:H111),"N/A"),0) -> 0 | O15: =IF(U15=0,SUM(H101:H111),0) -> 6 | P15: =IF(U15=0,1-N15,0) -> 1 | Q15: =IF(U15=0,IF($N15<=0.25,$N15,0),0) -> 0 | R15: =IF(U15=0,IF(AND($N15>=0.25001,$N15<=0.5),$N15,0),0) -> 0 | S15: =IF(U15=0,IF(AND($N15>=0.50001,$N15<=(GlobalSettings!$C$6-0.00001)),$N15,0),0) -> 0 | T15: =IF(U15=0,IF($N15>=GlobalSettings!$C$6,$N15,0),0) -> 0 | U15: =IF('Control 13'!$F$2="Not Assessed",1,0) -> 0 | V15: 0.966 | W15: =GlobalSettings!$C$6 -> 0.7
B16: 3.02 | C16: Establish and Maintain a Data Inventory | D16: 1 | E16: 8 | F16: 0 | G16: =IF(OR(E16>10,F16>5),"Critical",IF(OR(AND(E16>0,E16<11),AND(F16>0,F16<6)),"High","Medium")) -> High | H16: =IF(OR(GlobalSettings!$C$2=0,D16<=GlobalSettings!$C$2),IF(G16="Critical",5,IF(G16="High",3,(IF(G16="Medium",1,0)))),0) -> 3 | I16: ='Control 03'!F28 -> 0 | J16: =IF(OR(GlobalSettings!$C$2=0,D16<=GlobalSettings!$C$2),'Control 03'!E30,"") -> Safeguard Scoring Incomplete | L16: 14 | M16: Security Awareness and Skills Training | N16: =IFERROR(IF(U16=0,SUMPRODUCT(I112:I120,H112:H120)/SUM(H112:H120),"N/A"),0) -> 0 | O16: =IF(U16=0,SUM(H112:H120),0) -> 11 | P16: =IF(U16=0,1-N16,0) -> 1 | Q16: =IF(U16=0,IF($N16<=0.25,$N16,0),0) -> 0 | R16: =IF(U16=0,IF(AND($N16>=0.25001,$N16<=0.5),$N16,0),0) -> 0 | S16: =IF(U16=0,IF(AND($N16>=0.50001,$N16<=(GlobalSettings!$C$6-0.00001)),$N16,0),0) -> 0 | T16: =IF(U16=0,IF($N16>=GlobalSettings!$C$6,$N16,0),0) -> 0 | U16: =IF('Control 14'!$F$2="Not Assessed",1,0) -> 0 | V16: 0.83832 | W16: =GlobalSettings!$C$6 -> 0.7
B17: 3.03 | C17: Configure Data Access Control Lists | D17: 1 | E17: 0 | F17: 2 | G17: =IF(OR(E17>10,F17>5),"Critical",IF(OR(AND(E17>0,E17<11),AND(F17>0,F17<6)),"High","Medium")) -> High | H17: =IF(D17<=GlobalSettings!$C$2,IF(G17="Critical",5,IF(G17="High",3,(IF(G17="Medium",1,0)))),0) -> 0 | I17: ='Control 03'!F43 -> 0 | J17: =IF(D17<=GlobalSettings!$C$2,'Control 03'!E45,"") | L17: 15 | M17: Service Provider Management | N17: =IFERROR(IF(U17=0,SUMPRODUCT(I121:I127,H121:H127)/SUM(H121:H127),"N/A"),0) -> 0 | O17: =IF(U17=0,SUM(H121:H127),0) -> 3 | P17: =IF(U17=0,1-N17,0) -> 1 | Q17: =IF(U17=0,IF($N17<=0.25,$N17,0),0) -> 0 | R17: =IF(U17=0,IF(AND($N17>=0.25001,$N17<=0.5),$N17,0),0) -> 0 | S17: =IF(U17=0,IF(AND($N17>=0.50001,$N17<=(GlobalSettings!$C$6-0.00001)),$N17,0),0) -> 0 | T17: =IF(U17=0,IF($N17>=GlobalSettings!$C$6,$N17,0),0) -> 0 | U17: =IF('Control 15'!$F$2="Not Assessed",1,0) -> 0 | V17: 0.458304 | W17: =GlobalSettings!$C$6 -> 0.7
B18: 3.04 | C18: Enforce Data Retention | D18: 1 | E18: 0 | F18: 1 | G18: =IF(OR(E18>10,F18>5),"Critical",IF(OR(AND(E18>0,E18<11),AND(F18>0,F18<6)),"High","Medium")) -> High | H18: =IF(OR(GlobalSettings!$C$2=0,D18<=GlobalSettings!$C$2),IF(G18="Critical",5,IF(G18="High",3,(IF(G18="Medium",1,0)))),0) -> 3 | I18: ='Control 03'!F58 -> 0 | J18: =IF(OR(GlobalSettings!$C$2=0,D18<=GlobalSettings!$C$2),'Control 03'!E60,"") -> Safeguard Scoring Incomplete | L18: 16 | M18: Application Software Security | N18: =IFERROR(IF(U18=0,SUMPRODUCT(I128:I141,H128:H141)/SUM(H128:H141),"N/A"),0) -> N/A | O18: =IF(U18=0,SUM(H128:H141),0) -> 0 | P18: =IF(U18=0,1-N18,0) -> 0 | Q18: =IF(U18=0,IF($N18<=0.25,$N18,0),0) -> 0 | R18: =IF(U18=0,IF(AND($N18>=0.25001,$N18<=0.5),$N18,0),0) -> 0 | S18: =IF(U18=0,IF(AND($N18>=0.50001,$N18<=(GlobalSettings!$C$6-0.00001)),$N18,0),0) -> 0 | T18: =IF(U18=0,IF($N18>=GlobalSettings!$C$6,$N18,0),0) -> 0 | U18: =IF('Control 16'!$F$2="Not Assessed",1,0) -> 1 | V18: 0 | W18: =GlobalSettings!$C$6 -> 0.7
B19: 3.05 | C19: Securely Dispose of Data | D19: 1 | E19: 0 | F19: 0 | G19: =IF(OR(E19>10,F19>5),"Critical",IF(OR(AND(E19>0,E19<11),AND(F19>0,F19<6)),"High","Medium")) -> Medium | H19: =IF(OR(GlobalSettings!$C$2=0,D19<=GlobalSettings!$C$2),IF(G19="Critical",5,IF(G19="High",3,(IF(G19="Medium",1,0)))),0) -> 1 | I19: ='Control 03'!F72 -> 0 | J19: =IF(OR(GlobalSettings!$C$2=0,D19<=GlobalSettings!$C$2),'Control 03'!E74,"") -> Safeguard Scoring Incomplete | L19: 17 | M19: Incident Response Management | N19: =IFERROR(IF(U19=0,SUMPRODUCT(I142:I150,H142:H150)/SUM(H142:H150),"N/A"),0) -> 0 | O19: =IF(U19=0,SUM(H142:H150),0) -> 3 | P19: =IF(U19=0,1-N19,0) -> 1 | Q19: =IF(U19=0,IF($N19<=0.25,$N19,0),0) -> 0 | R19: =IF(U19=0,IF(AND($N19>=0.25001,$N19<=0.5),$N19,0),0) -> 0 | S19: =IF(U19=0,IF(AND($N19>=0.50001,$N19<=(GlobalSettings!$C$6-0.00001)),$N19,0),0) -> 0 | T19: =IF(U19=0,IF($N19>=GlobalSettings!$C$6,$N19,0),0) -> 0 | U19: =IF('Control 17'!$F$2="Not Assessed",1,0) -> 0 | V19: 0.458192 | W19: =GlobalSettings!$C$6 -> 0.7
B20: 3.06 | C20: Encrypt Data on End-User Devices | D20: 1 | E20: 0 | F20: 0 | G20: =IF(OR(E20>10,F20>5),"Critical",IF(OR(AND(E20>0,E20<11),AND(F20>0,F20<6)),"High","Medium")) -> Medium | H20: =IF(OR(GlobalSettings!$C$2=0,D20<=GlobalSettings!$C$2),IF(G20="Critical",5,IF(G20="High",3,(IF(G20="Medium",1,0)))),0) -> 1 | I20: ='Control 03'!F84 -> 0 | J20: =IF(OR(GlobalSettings!$C$2=0,D20<=GlobalSettings!$C$2),'Control 03'!E86,"") -> Safeguard Scoring Incomplete | L20: 18 | M20: Penetration Testing | N20: =IFERROR(IF(U20=0,SUMPRODUCT(I151:I155,H151:H155)/SUM(H151:H155),"N/A"),0) -> 0 | O20: =IF(U20=0,SUM(H151:H155),0) -> 3 | P20: =IF(U20=0,1-N20,0) -> 1 | Q20: =IF(U20=0,IF($N20<=0.25,$N20,0),0) -> 0 | R20: =IF(U20=0,IF(AND($N20>=0.25001,$N20<=0.5),$N20,0),0) -> 0 | S20: =IF(U20=0,IF(AND($N20>=0.50001,$N20<=(GlobalSettings!$C$6-0.00001)),$N20,0),0) -> 0 | T20: =IF(U20=0,IF($N20>=GlobalSettings!$C$6,$N20,0),0) -> 0 | U20: =IF('Control 18'!$F$2="Not Assessed",1,0) -> 0 | V20: 0.8844 | W20: =GlobalSettings!$C$6 -> 0.7
B21: 3.07 | C21: Establish and Maintain a Data Classification Scheme | D21: 2 | E21: 0 | F21: 0 | G21: =IF(OR(E21>10,F21>5),"Critical",IF(OR(AND(E21>0,E21<11),AND(F21>0,F21<6)),"High","Medium")) -> Medium | H21: =IF(OR(GlobalSettings!$C$2=0,D21<=GlobalSettings!$C$2),IF(G21="Critical",5,IF(G21="High",3,(IF(G21="Medium",1,0)))),0) -> 1 | I21: ='Control 03'!F99 -> 0 | J21: =IF(OR(GlobalSettings!$C$2=0,D21<=GlobalSettings!$C$2),'Control 03'!E101,"") -> Safeguard Scoring Incomplete
B22: 3.08 | C22: Document Data Flows | D22: 2 | E22: 0 | F22: 0 | G22: =IF(OR(E22>10,F22>5),"Critical",IF(OR(AND(E22>0,E22<11),AND(F22>0,F22<6)),"High","Medium")) -> Medium | H22: =IF(D22<=GlobalSettings!$C$2,IF(G22="Critical",5,IF(G22="High",3,(IF(G22="Medium",1,0)))),0) -> 0 | I22: ='Control 03'!F110 -> 0 | J22: =IF(D22<=GlobalSettings!$C$2,'Control 03'!E112,"") | M22: Overall Score: | N22: =IFERROR(SUMPRODUCT(N3:N20,$O$3:$O$20)/SUM($O$3:$O$20),0) -> 0 | O22: =SUM(O3:O20) -> 144 | P22: =1-N22 -> 1 | Q22: =IF($N22<=0.25,$N22,0) -> 0 | R22: =IF(AND($N22>=0.25001,$N22<=0.5),$N22,0) -> 0 | S22: =IF(AND($N22>=0.50001,$N22<=(GlobalSettings!$C$6-0.00001)),$N22,0) -> 0 | T22: =IF($N22>=GlobalSettings!$C$6,$N22,0) -> 0 | V22: =IFERROR(SUMPRODUCT(V3:V20,$O$3:$O$20)/SUM($O$3:$O$20),0) -> 0.66374911
B23: 3.09 | C23: Encrypt Data on Removable Media | D23: 2 | E23: 0 | F23: 0 | G23: =IF(OR(E23>10,F23>5),"Critical",IF(OR(AND(E23>0,E23<11),AND(F23>0,F23<6)),"High","Medium")) -> Medium | H23: =IF(D23<=GlobalSettings!$C$2,IF(G23="Critical",5,IF(G23="High",3,(IF(G23="Medium",1,0)))),0) -> 0 | I23: ='Control 03'!F121 -> 0 | J23: =IF(D23<=GlobalSettings!$C$2,'Control 03'!E123,"")
B24: 3.1 | C24: Encrypt Sensitive Data in Transit | D24: 2 | E24: 0 | F24: 1 | G24: =IF(OR(E24>10,F24>5),"Critical",IF(OR(AND(E24>0,E24<11),AND(F24>0,F24<6)),"High","Medium")) -> High | H24: =IF(D24<=GlobalSettings!$C$2,IF(G24="Critical",5,IF(G24="High",3,(IF(G24="Medium",1,0)))),0) -> 0 | I24: ='Control 03'!F130 -> 0 | J24: =IF(D24<=GlobalSettings!$C$2,'Control 03'!E132,"")
B25: 3.11 | C25: Encrypt Sensitive Data at Rest | D25: 2 | E25: 0 | F25: 2 | G25: =IF(OR(E25>10,F25>5),"Critical",IF(OR(AND(E25>0,E25<11),AND(F25>0,F25<6)),"High","Medium")) -> High | H25: =IF(D25<=GlobalSettings!$C$2,IF(G25="Critical",5,IF(G25="High",3,(IF(G25="Medium",1,0)))),0) -> 0 | I25: ='Control 03'!F140 -> 0 | J25: =IF(D25<=GlobalSettings!$C$2,'Control 03'!E142,"") | M25: Metric | N25: Score | O25: Scale | P25: Fill | Q25: Size
B26: 3.12 | C26: Segment Data Processing and Storage Based on Sensitivity | D26: 2 | E26: 0 | F26: 5 | G26: =IF(OR(E26>10,F26>5),"Critical",IF(OR(AND(E26>0,E26<11),AND(F26>0,F26<6)),"High","Medium")) -> High | H26: =IF(D26<=GlobalSettings!$C$2,IF(G26="Critical",5,IF(G26="High",3,(IF(G26="Medium",1,0)))),0) -> 0 | I26: ='Control 03'!F149 -> 0 | J26: =IF(D26<=GlobalSettings!$C$2,'Control 03'!E151,"") | M26: CIS CAS Overall Average Score | N26: =N22 -> 0 | O26: 1 | P26: =N26-(Q26/2) -> -0.01 | Q26: 0.02
B27: 3.13 | C27: Deploy a Data Loss Prevention Solution | D27: 3 | E27: 0 | F27: 0 | G27: =IF(OR(E27>10,F27>5),"Critical",IF(OR(AND(E27>0,E27<11),AND(F27>0,F27<6)),"High","Medium")) -> Medium | H27: =IF(D27<=GlobalSettings!$C$2,IF(G27="Critical",5,IF(G27="High",3,(IF(G27="Medium",1,0)))),0) -> 0 | I27: ='Control 03'!F160 -> 0 | J27: =IF(D27<=GlobalSettings!$C$2,'Control 03'!E162,"")
B28: 3.14 | C28: Log Sensitive Data Access | D28: 3 | E28: 0 | F28: 0 | G28: =IF(OR(E28>10,F28>5),"Critical",IF(OR(AND(E28>0,E28<11),AND(F28>0,F28<6)),"High","Medium")) -> Medium | H28: =IF(D28<=GlobalSettings!$C$2,IF(G28="Critical",5,IF(G28="High",3,(IF(G28="Medium",1,0)))),0) -> 0 | I28: ='Control 03'!F171 -> 0 | J28: =IF(D28<=GlobalSettings!$C$2,'Control 03'!E173,"") | M28: Overall Assessment Completion | N28: =COUNTIF(J3:J155,"Safeguard Scoring Complete")/(COUNTIF(J3:J155,"Safeguard Scoring Complete")+COUNTIF(J3:J155,"Safeguard Scoring Incomplete")) -> 0
B29: 4.01 | C29: Establish and Maintain a Secure Configuration Process | D29: 1 | E29: 43 | F29: 10 | G29: =IF(OR(E29>10,F29>5),"Critical",IF(OR(AND(E29>0,E29<11),AND(F29>0,F29<6)),"High","Medium")) -> Critical | H29: =IF(OR(GlobalSettings!$C$2=0,D29<=GlobalSettings!$C$2),IF(G29="Critical",5,IF(G29="High",3,(IF(G29="Medium",1,0)))),0) -> 5 | I29: ='Control 04'!F12 -> 0 | J29: =IF(OR(GlobalSettings!$C$2=0,D29<=GlobalSettings!$C$2),'Control 04'!E14,"") -> Safeguard Scoring Incomplete
B30: 4.02 | C30: Establish and Maintain a Secure Configuration Process for Network Infrastructure | D30: 1 | E30: 7 | F30: 3 | G30: =IF(OR(E30>10,F30>5),"Critical",IF(OR(AND(E30>0,E30<11),AND(F30>0,F30<6)),"High","Medium")) -> High | H30: =IF(D30<=GlobalSettings!$C$2,IF(G30="Critical",5,IF(G30="High",3,(IF(G30="Medium",1,0)))),0) -> 0 | I30: ='Control 04'!F24 -> 0 | J30: =IF(D30<=GlobalSettings!$C$2,'Control 04'!E26,"")
B31: 4.03 | C31: Configure Automatic Session Locking on Enterprise Assets | D31: 1 | E31: 0 | F31: 0 | G31: =IF(OR(E31>10,F31>5),"Critical",IF(OR(AND(E31>0,E31<11),AND(F31>0,F31<6)),"High","Medium")) -> Medium | H31: =IF(OR(GlobalSettings!$C$2=0,D31<=GlobalSettings!$C$2),IF(G31="Critical",5,IF(G31="High",3,(IF(G31="Medium",1,0)))),0) -> 1 | I31: ='Control 04'!F36 -> 0 | J31: =IF(OR(GlobalSettings!$C$2=0,D31<=GlobalSettings!$C$2),'Control 04'!E38,"") -> Safeguard Scoring Incomplete
B32: 4.04 | C32: Implement and Manage a Firewall on Servers | D32: 1 | E32: 0 | F32: 3 | G32: =IF(OR(E32>10,F32>5),"Critical",IF(OR(AND(E32>0,E32<11),AND(F32>0,F32<6)),"High","Medium")) -> High | H32: =IF(OR(GlobalSettings!$C$2=0,D32<=GlobalSettings!$C$2),IF(G32="Critical",5,IF(G32="High",3,(IF(G32="Medium",1,0)))),0) -> 3 | I32: ='Control 04'!F48 -> 0 | J32: =IF(OR(GlobalSettings!$C$2=0,D32<=GlobalSettings!$C$2),'Control 04'!E50,"") -> Safeguard Scoring Incomplete
B33: 4.05 | C33: Implement and Manage a Firewall on End-User Devices | D33: 1 | E33: 0 | F33: 0 | G33: =IF(OR(E33>10,F33>5),"Critical",IF(OR(AND(E33>0,E33<11),AND(F33>0,F33<6)),"High","Medium")) -> Medium | H33: =IF(OR(GlobalSettings!$C$2=0,D33<=GlobalSettings!$C$2),IF(G33="Critical",5,IF(G33="High",3,(IF(G33="Medium",1,0)))),0) -> 1 | I33: ='Control 04'!F65 -> 0 | J33: =IF(OR(GlobalSettings!$C$2=0,D33<=GlobalSettings!$C$2),'Control 04'!E67,"") -> Safeguard Scoring Incomplete
B34: 4.06 | C34: Securely Manage Enterprise Assets and Software | D34: 1 | E34: 0 | F34: 0 | G34: =IF(OR(E34>10,F34>5),"Critical",IF(OR(AND(E34>0,E34<11),AND(F34>0,F34<6)),"High","Medium")) -> Medium | H34: =IF(D34<=GlobalSettings!$C$2,IF(G34="Critical",5,IF(G34="High",3,(IF(G34="Medium",1,0)))),0) -> 0 | I34: ='Control 04'!F76 -> 0 | J34: =IF(D34<=GlobalSettings!$C$2,'Control 04'!E78,"")
B35: 4.07 | C35: Manage Default Accounts on Enterprise Assets and Software | D35: 1 | E35: 0 | F35: 10 | G35: =IF(OR(E35>10,F35>5),"Critical",IF(OR(AND(E35>0,E35<11),AND(F35>0,F35<6)),"High","Medium")) -> Critical | H35: =IF(OR(GlobalSettings!$C$2=0,D35<=GlobalSettings!$C$2),IF(G35="Critical",5,IF(G35="High",3,(IF(G35="Medium",1,0)))),0) -> 5 | I35: ='Control 04'!F88 -> 0 | J35: =IF(OR(GlobalSettings!$C$2=0,D35<=GlobalSettings!$C$2),'Control 04'!E90,"") -> Safeguard Scoring Incomplete
B36: 4.08 | C36: Uninstall or Disable Unnecessary Services on Enterprise Assets and Software | D36: 2 | E36: 0 | F36: 6 | G36: =IF(OR(E36>10,F36>5),"Critical",IF(OR(AND(E36>0,E36<11),AND(F36>0,F36<6)),"High","Medium")) -> Critical | H36: =IF(D36<=GlobalSettings!$C$2,IF(G36="Critical",5,IF(G36="High",3,(IF(G36="Medium",1,0)))),0) -> 0 | I36: ='Control 04'!F101 -> 0 | J36: =IF(D36<=GlobalSettings!$C$2,'Control 04'!E103,"")
B37: 4.09 | C37: Configure Trusted DNS Servers on Enterprise Assets | D37: 2 | E37: 0 | F37: 0 | G37: =IF(OR(E37>10,F37>5),"Critical",IF(OR(AND(E37>0,E37<11),AND(F37>0,F37<6)),"High","Medium")) -> Medium | H37: =IF(D37<=GlobalSettings!$C$2,IF(G37="Critical",5,IF(G37="High",3,(IF(G37="Medium",1,0)))),0) -> 0 | I37: ='Control 04'!F111 -> 0 | J37: =IF(D37<=GlobalSettings!$C$2,'Control 04'!E113,"")
B38: 4.1 | C38: Enforce Automatic Device Lockout on Portable End-User Devices | D38: 2 | E38: 0 | F38: 1 | G38: =IF(OR(E38>10,F38>5),"Critical",IF(OR(AND(E38>0,E38<11),AND(F38>0,F38<6)),"High","Medium")) -> High | H38: =IF(D38<=GlobalSettings!$C$2,IF(G38="Critical",5,IF(G38="High",3,(IF(G38="Medium",1,0)))),0) -> 0 | I38: ='Control 04'!F122 -> 0 | J38: =IF(D38<=GlobalSettings!$C$2,'Control 04'!E124,"")
B39: 4.11 | C39: Enforce Remote Wipe Capability on Portable End-User Devices | D39: 2 | E39: 0 | F39: 0 | G39: =IF(OR(E39>10,F39>5),"Critical",IF(OR(AND(E39>0,E39<11),AND(F39>0,F39<6)),"High","Medium")) -> Medium | H39: =IF(D39<=GlobalSettings!$C$2,IF(G39="Critical",5,IF(G39="High",3,(IF(G39="Medium",1,0)))),0) -> 0 | I39: ='Control 04'!F131 -> 0 | J39: =IF(D39<=GlobalSettings!$C$2,'Control 04'!E133,"")
B40: 4.12 | C40: Separate Enterprise Workspaces on Mobile End-User Devices | D40: 3 | E40: 0 | F40: 0 | G40: =IF(OR(E40>10,F40>5),"Critical",IF(OR(AND(E40>0,E40<11),AND(F40>0,F40<6)),"High","Medium")) -> Medium | H40: =IF(D40<=GlobalSettings!$C$2,IF(G40="Critical",5,IF(G40="High",3,(IF(G40="Medium",1,0)))),0) -> 0 | I40: ='Control 04'!F143 -> 0 | J40: =IF(D40<=GlobalSettings!$C$2,'Control 04'!E145,"")
B41: 5.01 | C41: Establish and Maintain an Inventory of Accounts | D41: 1 | E41: 6 | F41: 2 | G41: =IF(OR(E41>10,F41>5),"Critical",IF(OR(AND(E41>0,E41<11),AND(F41>0,F41<6)),"High","Medium")) -> High | H41: =IF(OR(GlobalSettings!$C$2=0,D41<=GlobalSettings!$C$2),IF(G41="Critical",5,IF(G41="High",3,(IF(G41="Medium",1,0)))),0) -> 3 | I41: ='Control 05'!F16 -> 0 | J41: =IF(OR(GlobalSettings!$C$2=0,D41<=GlobalSettings!$C$2),'Control 05'!E18,"") -> Safeguard Scoring Incomplete
...

Sheet Control 01
C2: Control 01: Inventory and Control of Enterprise Assets | F2: Assessed | G2: https://cas.docs.cisecurity.org/en/latest/source/Controls1/
A4: 0 | B4: 1 | C4: 1.01 | D4: Establish and Maintain a Detailed Enterprise Asset Inventory | F4: Measure | G4: Notes
A5: 0 | B5: 1 | D5: M1 | E5: Enterprise Asset Inventory (GV01) | F5: =IF(Artifacts!$E$3="Artifact Provided",1,0) -> 0 | G5: "1" if provided, "0" if not provided
A6: 0 | B6: 1 | D6: M1.a | E6: Count of Assets in GV01
A7: 0 | B7: 1 | D7: M2 | E7: Count of Assets Detected since last update to GV01 | G7: Count of items in Aggregate Enterprise Asset Inventory - The enterprise's list of all devices detected, manually or through automated scans, since the last update to GV1
A8: 0 | B8: 1 | D8: M3 | E8: Count of Assets in GV01 Detected
A9: 0 | B9: 1 | D9: M4 | E9: Count of Assets in GV01 Not Detected | F9: =F6-F8 -> 0 | G9: Difference between M1.a and M3
A10: 0 | B10: 1 | D10: M5 | E10: Count of Assets Detected not in GV01 (GV02) | F10: =F7-F8 -> 0 | G10: Difference between M2 and M3
A11: 0 | B11: 1 | D11: M6 | E11: Count of Required Elements in GV01 | G11: The following data elements are required for each entry in the Asset Inventory: hardware address, machine name, asset owner, department, and whether the asset is approved to connect to the network.
A12: 0 | B12: 1 | D12: M7 | E12: Count of Missing Elements in GV01 | F12: =(F6*5)-F11 -> 0 | G12: Difference between expected elements (M1.a*5) and M6
A13: 0 | B13: 1 | D13: M8 | E13: Months since last update to GV01 | F13: =DATEDIF(Artifacts!$F$3,GlobalSettings!$C$4,"m") -> 1508 | G13: Count of months since date provided for GV01 and Assessment Date
A14: 0 | B14: 1 | E14: Safeguard 01.01 Accuracy Score | F14: =IFERROR(F8/F7,0) -> 0 | G14: M3 / M2
A15: 0 | B15: 1 | E15: Safeguard 01.01 Completeness Score | F15: =IFERROR(F11/(F6*5),0) -> 0 | G15: M7 / (M1.a*5)
A16: 0 | B16: 1 | E16: Safeguard 01.01 Average Score | F16: =IF(F5=0,0,IF(F13<=6,AVERAGE(F14,F15),IF(GlobalSettings!$C$12="No",0,AVERAGE(F14,F15)*0.5))) -> 0 | G16: If GV01 is not provided, Safeguard receives a "0" score | If not updated in the last 6 months, Safeguard receives a "0" or reduced score
A18: 0 | B18: 1 | E18: Safeguard Scoring Incomplete | F18: NOTES:
A20: 0 | B20: 1 | C20: 1.02 | D20: Address Unauthorized Assets | F20: Measure | G20: Notes
A21: 0 | B21: 1 | D21: M1 | E21: Enterprise Asset Inventory (GV01) | F21: =IF(Artifacts!$E$3="Artifact Provided",1,0) -> 0 | G21: "1" if provided, "0" if not provided
A22: 0 | B22: 1 | D22: M2 | E22: Count of Assets in GV02 | F22: =F10 -> 0 | G22: Safeguard 1.01, M5
A23: 0 | B23: 1 | D23: M3 | E23: Enterprise Defined Timeframe (in days) for Addressing Unauthorized Assets
A24: 0 | B24: 1 | D24: M4 | E24: Count of Assets in GV02 with a "First Seen" date greater than M3 days prior to the Assessment
A25: 0 | B25: 1 | E25: The ratio of unaccounted for, unauthorized assets, to the total assets in the asset inventory. | F25: =IFERROR(F24/F22,0) -> 0 | G25: M4 / M2
A26: 0 | B26: 1 | E26: Safeguard 01.02 Final Score | F26: =IF(OR(F21=0,F23<>1),0,IF(F23>7,0,(1-F25))) -> 0 | G26: If GV01 is not provided or M3 is greater than 1 day, Safeguard receives a "0" score
A28: 0 | B28: 1 | E28: Safeguard Scoring Incomplete | F28: NOTES:
A30: 9 | B30: 2 | C30: 1.03 | D30: Utilize an Active Discovery Tool | F30: Measure | G30: Notes
A31: 9 | B31: 2 | D31: M1 | E31: Count of leasable IP addresses within Enterprise Subnet | G31: Enumerate all IP subnets configured as leasable (IPAM)
A32: 9 | B32: 2 | D32: M2 | E32: Count of leasable IP addresses scanned by Enterprise Asset Discovery Tools | G32: Enumerate all IP subnets scanned
A33: 9 | B33: 2 | D33: M3 | E33: Count of Properly Configured Asset Discovery Tools | G33: Enumerate those tools that are compliant
A34: 9 | B34: 2 | D34: M4 | E34: Count of Improperly Configured Asset Discovery Tools | F34: =F35-F33 -> 0 | G34: Tools that are not compliant: Difference between M5 and M3
A35: 9 | B35: 2 | D35: M5 | E35: Count of Asset Discovery Tools used by the Enterprise
A36: 9 | B36: 2 | D36: M6 | E36: Count of Assets in GV01 | F36: =F6 -> 0 | G36: 1.01 M1.a
A37: 9 | B37: 2 | D37: M7 | E37: Timeframe (in hours) between Active Discovery Scans
A38: 9 | B38: 2 | E38: IP Address Discovery Coverage | F38: =IFERROR(F32/F31,0) -> 0 | G38: M2 / M1
A39: 9 | B39: 2 | E39: Tool Compliance Ratio | F39: =IFERROR(F33/F35,0) -> 0 | G39: M3 / M5
A40: 9 | B40: 2 | E40: Safeguard 01.03 Average Score | F40: =IF(OR(F35=0,F37>24),0,AVERAGE(F38,F39)) -> 0 | G40: If M5 = 0, Safeguard receives a "0" score | If M7 > 24 hours, Safeguard receives a "0" score
A42: 9 | B42: 2 | E42: Safeguard Scoring Incomplete | F42: NOTES:
A44: 9 | B44: 2 | C44: 1.04 | D44: Use Dynamic Host Configuration Protocol (DHCP) Logging to Update Enterprise Asset Inventory | F44: Measure | G44: Notes
A45: 9 | B45: 2 | D45: M1 | E45: Count of DHCP Servers
A46: 9 | B46: 2 | D46: M2 | E46: Count of DHCP Servers with Logging Enabled | G46: For each DHCP server, enumerate those where DHCP logging is enabled
A47: 9 | B47: 2 | D47: M3 | E47: Count of CMDB Servers (GV41)
A48: 9 | B48: 2 | D48: M4 | E48: Count of CMDB servers configured to use DHCP logs to update IP addresses | G48: For each CMDB server, enumerate those where DHCP logs are used to update IP addresses
...

Sheet Control 02
C2: Control 02: Inventory and Control of Software Assets | F2: Assessed | G2: https://cas.docs.cisecurity.org/en/latest/source/Controls2/
A4: 0 | B4: 1 | C4: 2.01 | D4: Establish and Maintain a Software Inventory | F4: Measure | G4: Notes
A5: 0 | B5: 1 | D5: M1 | E5: Authorized Software Inventory (GV05) | F5: =IF(Artifacts!$E$13="Artifact Provided",1,0) -> 0 | G5: "1" if provided, "0" if not provided
A6: 0 | B6: 1 | D6: M1.a | E6: Count of Software in GV05 | F6: 0
A7: 0 | B7: 1 | D7: M2 | E7: Sum of Required Elements in GV05 | F7: =SUM(F8:F11) -> 0 | G7: Check GV5 for completeness of detailed information
A8: 0 | B8: 1 | D8: M2.a | E8: Check for required data element: software title | G8: "1" if yes, "0" if no
A9: 0 | B9: 1 | D9: M2.b | E9: Check for required data element: publisher | G9: "1" if yes, "0" if no
A10: 0 | B10: 1 | D10: M2.c | E10: Check for required data element: software [first] install date | G10: "1" if yes, "0" if no
A11: 0 | B11: 1 | D11: M2.d | E11: Check for required data element: business purpose | G11: "1" if yes, "0" if no
A12: 0 | B12: 1 | D12: M2.e | E12: Check for required data element: supported/unsupported designation. | G12: "1" if yes, "0" if no
D13: M2.f | E13: Count of all elements present across GV05 | F13: 0 | G13: The following data elements are required for each entry in the Software Inventory: software title, publisher, software [first] install date, business purpose, supported/unsupported designation.
A14: 0 | B14: 1 | D14: M3 | E14: Count of Items in GV05 With Incomplete or Missing Information | F14: 0 | G14: Items that have missing or incomplete information
A15: 0 | B15: 1 | D15: M4 | E15: Months Since Last Update to GV05 | F15: =DATEDIF(Artifacts!$F$13,GlobalSettings!$C$4,"m") -> 1508 | G15: Count of months since date provided for GV05
A16: 0 | B16: 1 | E16: What percentage of the current enterprise asset inventory contains necessary detailed information? | F16: =IFERROR(F13/(F6*4),0) -> 0 | G16: M2 / (M1.a*4)
A17: 0 | B17: 1 | E17: Safeguard 02.01 Accuracy Score | F17: =IF(F5=0,0,IF(F15<=6,F16,IF(GlobalSettings!$C$12="No",0,F16*0.5))) -> 0 | G17: If M1 = "0" Safeguard receives a "0" score | If M4 > 6, Safeguard receives a "0" or reduced score
A19: 0 | B19: 1 | C19: 1 | E19: Safeguard Scoring Incomplete | F19: NOTES:
A21: 0 | B21: 1 | C21: 2.02 | D21: Ensure Authorized Software is Currently Supported | F21: Measure | G21: Notes
A22: 0 | B22: 1 | D22: M1 | E22: Authorized Software Inventory (GV05) | F22: =F5 -> 0 | G22: "1" if provided, "0" if not provided
A23: 0 | B23: 1 | D23: M1.a | E23: Count of Software in GV05 | F23: =F6 -> 0
A24: 0 | B24: 1 | D24: M2 | E24: Count of Items in GV05 That Are Mislabeled as "Unsupported" | G24: Enumerate each item labeled "unsupported" but "supported"
A25: 0 | B25: 1 | D25: M3 | E25: Count of Items in GV05 That Are Mislabeled as "Supported" | G25: Enumerate each item labeled "supported" but "unsupported"
A26: 0 | B26: 1 | D26: M4 | E26: Count of Unsupported Items | G26: Identify and note truly "unsupported" items from M2 and M3
A27: 0 | B27: 1 | D27: M5 | E27: Count of Items in GV05 That Are No Longer Supported, But Exception Documentation Exists | G27: Note items that do have appropriate exception documentation
A28: 0 | B28: 1 | D28: M6 | E28: Count of Items in GV05 That Are No Longer Supported, But Exception Documentation Does NOT Exist | F28: =F26-F27 -> 0 | G28: Items that do not have appropriate exception documentation: M4-M5
A29: 0 | B29: 1 | D29: M7 | E29: Weeks Since Last Update to GV05 | F29: =DATEDIF(Artifacts!$F$13,GlobalSettings!$C$4,"d")/7 -> 6557.1429 | G29: Count of weeks between date provided for GV05 and Assessment Date
A30: 0 | B30: 1 | E30: Percentage of Unsupported Software In Use | F30: =IFERROR(F26/F23,0) -> 0 | G30: M4 / M1
A31: 0 | B31: 1 | E31: Percentage of Software Listed as "Supported" That is Actually Unsupported | F31: =IFERROR(F25/F23,0) -> 0 | G31: M3 / M1
A32: 0 | B32: 1 | E32: Percentage of Software Listed as "Unsupported" That is Actually Supported | F32: =IFERROR(F24/F23,0) -> 0 | G32: M2 / M1
A33: 0 | B33: 1 | E33: Percentage of Unsupported Software That Has Appropriate Exception Documentation | F33: =IFERROR(F27/F26,0) -> 0 | G33: M5 / M4
A34: 0 | B34: 1 | E34: Safeguard 02.02 Final Score | F34: =IF(F5=0,0,IF(F29<=4,(IFERROR(IF(F33=0,(1-F30),1-(F26-F27)/F23),0)),IF(GlobalSettings!$C$12="No",0,(IFERROR(IF(F33=0,(1-F30),1-(F26-F27)/F23),0))*0.5))) -> 0 | G34: The percentage of authorized software that is: currently supported OR is unsupported but has a documented exception | If M7 > 4, Safeguard receives a "0" or reduced score
A36: 0 | B36: 1 | E36: Safeguard Scoring Incomplete | F36: NOTES:
A38: 0 | B38: 1 | C38: 2.03 | D38: Address Unauthorized Software | F38: Measure | G38: Notes
A39: 0 | B39: 1 | D39: M1 | E39: Count of Software Intalled on a Sample of Assets | G39: Scan the assets identified as software capable enterprise assets (GV7) from GV1 and note software present on each asset
A40: 0 | B40: 1 | D40: M2 | E40: Count of Unauthorized Software Installed on Sampled Assets | G40: Enumerate unauthorized software identified on assets
A41: 0 | B41: 1 | D41: M3 | E41: Count of Unauthorized Software With a "First Discovered" Date that Exceeds The Allowable Timeframe for resolution of discovered unauthorized software
A42: 0 | B42: 1 | D42: M4 | E42: Defined Timeframe, in days, For Resolution of Discovered Unauthorized Software | F42: 1 | G42: Statewide Standards CM-8(3): "remove or quarantine unauthorized components … when detected"
A43: 0 | B43: 1 | E43: Percentage of Unauthorized Software from Sampled Assets | F43: =IFERROR(F40/F39,0) -> 0 | G43: M2 / M1
A44: 0 | B44: 1 | E44: Percentage of Unauthorized Software from Sampled Assets With a "First Discovered" Date that Exceeds The Allowable Timeframe For Resolution | F44: =IFERROR(F41/F39,0) -> 0 | G44: M3 / M1
A45: 0 | B45: 1 | E45: Safeguard 02.03 Final Score | F45: =IF(F39=0,0,IF(F42>1,0,(1-F44))) -> 0 | G45: If M4 > 1, Safeguard receives a "0" score
A47: 0 | B47: 1 | E47: Safeguard Scoring Incomplete | F47: NOTES:
...

Sheet Control 03
C2: Control 3: Data Protection | F2: Assessed | G2: https://cas.docs.cisecurity.org/en/latest/source/Controls3/
A4: 0 | B4: 1 | C4: 3.01 | D4: Establish and Maintain a Data Management Process | F4: Measure | G4: Notes
A5: 0 | B5: 1 | D5: M1 | E5: Does the Process Address Data Sensitivity (GV11) | G5: "1" if yes, "0" if no
A6: 0 | B6: 1 | D6: M2 | E6: Does the Process Capture Data Owners (GV13) | F6: 1 | G6: "1" if yes, "0" if no
A7: 0 | B7: 1 | D7: M3 | E7: Does the Process Include Guidance for Handling of Data (GV14) | G7: "1" if yes, "0" if no
A8: 0 | B8: 1 | D8: M4 | E8: Does the Process Include Data Retention Limits Based on Sensitivity of Data (GV15) | G8: "1" if yes, "0" if no
A9: 0 | B9: 1 | D9: M5 | E9: Does the Process Include Guidance on Disposal Requirements Based on Data Sensitivity (GV16) | G9: "1" if yes, "0" if no
A10: 0 | B10: 1 | D10: M6 | E10: Enterprise Data Management Process (GV10) | F10: =IF(Artifacts!E15="Artifact Provided",1,0) -> 0 | G10: "1" if provided, "0" if not provided
A11: 0 | B11: 1 | E11: The percentage of completeness for the enterprise's data management process. | F11: =IFERROR(SUM(F5:F9)/5,0) -> 0.2 | G11: (M1 + M2 + M3 + M4 + M5) / 5
A12: 0 | B12: 1 | E12: Safeguard 3.01 Final Score | F12: =IF(F10=0,0,F11) -> 0 | G12: If GV10 is not provided this Safeguard is measured at "0"
A14: 0 | B14: 1 | E14: Safeguard Scoring Incomplete | F14: NOTES:
A16: 0 | B16: 1 | C16: 3.02 | D16: Establish and Maintain a Data Inventory | F16: Measure | G16: Notes
A17: 0 | B17: 1 | D17: M1 | E17: Portion of Data Management Process Addressing Data Sensitivity (GV11) | F17: =F5 -> 0 | G17: 3.01 M1
A18: 0 | B18: 1 | D18: M2 | E18: Enumerate items in the Sensitive Data Inventory (GV12) that have Mapping to Sensitive Data Types | G18: Identify and enumerate items in the data set that have a mapping
A19: 0 | B19: 1 | D19: M3 | E19: Enumerate items in the Sensitive Data Inventory (GV12) that DO NOT have Mapping to Sensitive Data Types | F19: =F25-F18 -> 0 | G19: Items in the data set that do not have a mapping: M9 - M2
A20: 0 | B20: 1 | D20: M4 | E20: Enumerate items from M2 that have complete and correct mapping to both sensitivity designations, and to assets from GV01 | G20: Identify and enumerate items that have complete and correct mapping to asset and sensitivity
A21: 0 | B21: 1 | D21: M5 | E21: Enumerate items from M2 that have partial mapping to sensitivity designations only (e.g. no mapping to assets in GV01.) | F21: =F18-F20 -> 0 | G21: Items that have partial mapping to sensitivity: M2 - M4
A22: 0 | B22: 1 | D22: M6 | E22: Enumerate items from M3 that have partial mapping to assets only. | G22: Identify and enumerate items that have partial mapping to assets
A23: 0 | B23: 1 | D23: M7 | E23: Enumerate items that have not mapping at all (i.e. data that is not mapped to an asset in GV01 or to a data sensitivity designation.) | F23: =F25-(F18+F22) -> 0 | G23: Items that have no mapping at all: M9 - (M2 + M6)
A24: 0 | B24: 1 | D24: M8 | E24: Timeframe, in months, since the last update to the sensitive data inventory | F24: =DATEDIF(Artifacts!F16,GlobalSettings!C4,"m") -> 1508 | G24: Compare current date to Input 4 and capture timeframe in months
A25: 0 | B25: 1 | D25: M9 | E25: Count of all items in the organization's sensitive data inventory (GV12)
A26: 0 | B26: 1 | E26: Completeness of Sensitive Data Inventory | F26: =IFERROR(F20/F25,0) -> 0 | G26: M4 / M9
A27: 0 | B27: 1 | E27: Partial Completeness of Sensitive Data Inventory | F27: =IFERROR((F21+F22)/F25,0) -> 0 | G27: (M5 + M6) / M9
A28: 0 | B28: 1 | E28: Safeguard 3.02 Composite Score | F28: =IF(F17=0,0,IF(F24<=12,((F27*0.5)+F26),IF(GlobalSettings!$C$12="No",0,((F27*0.5)+F26)))) -> 0 | G28: (Partial Completeness Score * 0.5) + Completeness Score | If GV11 is not provided this Safeguard receives a failing score | If M8 is greater than 12, Safeguard receives a "0" or reduced score
A30: 0 | B30: 1 | E30: Safeguard Scoring Incomplete | F30: NOTES:
A32: 9 | B32: 1 | C32: 3.03 | D32: Configure Data Access Control Lists | F32: Measure | G32: Notes
A33: 9 | B33: 1 | D33: M1 | E33: Count of sensitive data types correctly mapped to user accounts per the data management process | G33: Identify and enumerate sensitive data correctly mapped to user accounts from GV22
A34: 9 | B34: 1 | D34: M2 | E34: Count of sensitive data not correctly mapped to user accounts per the data management process | F34: =F38-F33 -> 0 | G34: Sensitive data not correctly mapped to user accounts from GV22: M6 - M1
A35: 9 | B35: 1 | D35: M3 | E35: Count of assets storing sensitive data | G35: Identify and enumerate all assets storing sensitive data
A36: 9 | B36: 1 | D36: M4 | E36: Count of properly configured assets to support data access control | G36: Use GV3 to check and enumerate assets that are properly configured to only allow users as identified in M1
A37: 9 | B37: 1 | D37: M5 | E37: Count of improperly configured assets to support data access control | F37: =F35-F36 -> 0 | G37: Assets that are improperly configured to only allow users as identified in M2: M3 - M4
A38: 9 | B38: 1 | D38: M6 | E38: Count of Sensitive Data Types (GV17)
A39: 9 | B39: 1 | D39: M7 | E39: Portion of Data Management Process Capturing Data Owners (GV13) | F39: =F6 -> 1 | G39: 3.01 M2
A40: 9 | B40: 1 | D40: M8 | E40: Portion of Data Management Process Addressing Data Handling (GV14) | F40: =F7 -> 0 | G40: 3.01 M3
A41: 9 | B41: 1 | E41: Completeness of User Access Control | F41: =IFERROR(F33/F38,0) -> 0 | G41: M1 / M6
A42: 9 | B42: 1 | E42: Properly Configured Assets | F42: =IFERROR(F36/F35,0) -> 0 | G42: M4 / M3
A43: 9 | B43: 1 | E43: Safeguard 3.03 Average Score | F43: =IF(OR(F39=0,F40=0),0,AVERAGE(F41,F42)) -> 0 | G43: If GV13 or GV14 is not provided this Safeguard receives a "0" score.
A45: 9 | B45: 1 | E45: Safeguard Scoring Incomplete | F45: NOTES:
A47: 0 | B47: 1 | C47: 3.04 | D47: Enforce Data Retention | F47: Measure | G47: Notes
A48: 0 | B48: 1 | E48: Portion of Data Management Process defining Data Retention Limits (GV15) | F48: =F8 -> 0 | G48: 3.01 M4
...

Sheet Control 04
C2: Control #4: Secure Configuration of Enterprise Assets and Software | F2: Assessed | G2: https://cas.docs.cisecurity.org/en/latest/source/Controls4/
A4: 0 | B4: 1 | C4: 4.01 | D4: Establish and Maintain a Secure Configuration Process | F4: Measure | G4: Notes
A5: 0 | B5: 1 | D5: M1 | E5: Enterprise Asset Inventory (GV01) | F5: =IF(Artifacts!$E$3="Artifact Provided",1,0) -> 0 | G5: "1" if provided, "0" if not provided
A6: 0 | B6: 1 | D6: M2 | E6: Count of applicable enterprise assets in GV01 | G6: Identify and enumerate end-user devices, including portable and mobile, non-computing/IoT devices, and servers in GV1
A7: 0 | B7: 1 | D7: M3 | E7: Count of software (operating systems, web servers, browsers, databases, and office suites) installed on applicable enterprise assets | G7: Using the output of M2, identify and enumerate the software installed on the assets using GV5
A8: 0 | B8: 1 | D8: M4 | E8: Count of software that is listed in the configuration standard | G8: Enumerate software that is listed in the configuration standard GV3
A9: 0 | B9: 1 | D9: M5 | E9: Count of software that is not listed in the configuration standard | F9: =F7-F8 -> 0 | G9: Software that is not listed in the configuration standard GV3: M3 - M4
A10: 0 | B10: 1 | D10: M6 | E10: Months since last update to Configuration Standard for Operating Systems and Software (GV03.a) | F10: =DATEDIF(Artifacts!$F$4,GlobalSettings!$C$4,"m") -> 1508 | G10: Count of months since date provided for GV03.a and Assessment Date
A11: 0 | B11: 1 | E11: The percentage of authorized software with secure configuration standards documented and maintained. | F11: =IFERROR(F8/F7,0) -> 0 | G11: M4 / M3
A12: 0 | B12: 1 | E12: Safeguard 4.01 Final Score | F12: =IF(F10<=GlobalSettings!$C$8,F11,IF(GlobalSettings!$C$10="No",0,F11*(GlobalSettings!$C$6-0.01))) -> 0 | G12: If M6 > [defined timeframe], Safeguard receives a "0" score
A14: 0 | B14: 1 | E14: Safeguard Scoring Incomplete | F14: NOTES:
A16: 9 | B16: 1 | C16: 4.02 | D16: Establish and Maintain a Secure Configuration Process for Network Infrastructure | F16: Measure | G16: Notes
A17: 9 | B17: 1 | D17: M1 | E17: Enterprise Asset Inventory (GV01) | F17: =IF(Artifacts!$E$3="Artifact Provided",1,0) -> 0 | G17: "1" if provided, "0" if not provided
A18: 9 | B18: 1 | D18: M2 | E18: Count of applicable network infrastructure assets in GV01 | G18: Identify and enumerate network infrastructure assets in GV1
A19: 9 | B19: 1 | D19: M3 | E19: Count of software installed on applicable enterprise assets | G19: Using the output of M2, identify and enumerate the software installed on the assets using GV5
A20: 9 | B20: 1 | D20: M4 | E20: Count of software that is listed in the configuration standard | G20: Enumerate software that is listed in the configuration standard GV3
A21: 9 | B21: 1 | D21: M5 | E21: Count of software that is not listed in the configuration standard | F21: =F19-F20 -> 0 | G21: Software that is not listed in the configuration standard GV3: M3 - M4
A22: 9 | B22: 1 | D22: M6 | E22: Months since last update to Configuration Standard for Operating Systems and Software (GV03.a) | F22: =DATEDIF(Artifacts!$F$4,GlobalSettings!$C$4,"m") -> 1508 | G22: Count of months since date provided for GV03 and Assessment Date
A23: 9 | B23: 1 | E23: The percentage of authorized software with secure configuration standards documented and maintained. | F23: =IFERROR(F20/F19,0) -> 0 | G23: M4 / M3
A24: 9 | B24: 1 | E24: Safeguard 4.02 Final Score | F24: =IF(F22<=GlobalSettings!$C$8,F23,IF(GlobalSettings!$C$10="No",0,F23*(GlobalSettings!$C$6-0.01))) -> 0 | G24: If M6 > [defined timeframe], Safeguard receives a "0" score
A26: 9 | B26: 1 | E26: Safeguard Scoring Incomplete | F26: NOTES:
A28: 0 | B28: 1 | C28: 4.03 | D28: Configure Automatic Session Locking on Enterprise Assets | F28: Measure | G28: Notes
A29: 0 | B29: 1 | D29: M1 | E29: Count of assets capable of supporting automatic session locking | G29: Identify and enumerate assets within GV1 that support automatic session locking due to inactivity
A30: 0 | B30: 1 | D30: M2 | E30: Count of assets with authorized software installed to allow automatic session locking | G30: Use GV5 to identify and enumerate assets from Operation 1 with authorized software installed
A31: 0 | B31: 1 | D31: M3 | E31: Count of general computing assets with properly configured automatic session locking | G31: For general computing assets, enumerate those assets with properly configured automatic session locking
A32: 0 | B32: 1 | D32: M4 | E32: Count of general computing assets with improperly configured automatic session locking | G32: For general computing assets, enumerate those assets with improperly configured automatic session locking
A33: 0 | B33: 1 | D33: M5 | E33: Count of mobile assets with properly configured automatic session locking | G33: For mobile assets, enumerate those assets with properly configured automatic session locking
A34: 0 | B34: 1 | D34: M6 | E34: Count of mobile assets with improperly configured automatic session locking | G34: For mobile assets, enumerate those assets with improperly configured automatic session locking
A35: 0 | B35: 1 | E35: The percentage of assets properly configured for automatic session locking. | F35: =IFERROR((F31+F33)/F29,0) -> 0 | G35: (M3 + M5) / M1
A36: 0 | B36: 1 | E36: Safeguard 4.03 Final Score | F36: =F35 -> 0
A38: 0 | B38: 1 | E38: Safeguard Scoring Incomplete | F38: NOTES:
A40: 0 | B40: 1 | C40: 4.04 | D40: Implement and Manage a Firewall on Servers | F40: Measure | G40: Notes
A41: 0 | B41: 1 | D41: M1 | E41: Count of servers capable of hosting a firewall | G41: Identify and enumerate servers capable of hosting a firewall using GV1
A42: 0 | B42: 1 | D42: M2 | E42: Count of applications of hosting a firewall | G42: Identify and enumerate applications capable of hosting a firewall using GV5
A43: 0 | B43: 1 | D43: M3 | E43: Count of servers with properly configured firewalls | G43: Enumerate servers from Operation 1 with properly configured firewalls
A44: 0 | B44: 1 | D44: M4 | E44: Count of servers with improperly configured firewalls | F44: =F41-F43 -> 0 | G44: Servers with improperly configured firewalls: M1 - M3
A45: 0 | B45: 1 | D45: M5 | E45: Count of applications with properly configured firewalls | G45: Enumerate applications from Operation 2 with properly configured firewalls
A46: 0 | B46: 1 | D46: M6 | E46: Count of applications with improperly configured firewalls | F46: =F42-F45 -> 0 | G46: Spplications with improperly configured firewalls: M2 - M5
A47: 0 | B47: 1 | E47: The percentage of properly configured firewalls within the enterprise | F47: =IFERROR((F43+F45)/(F41+F42),0) -> 0 | G47: (M3 + M5) / (M1 + M2)
